<?xml version="1.0"?>
<robot name="night_bot">
  <link name="base_link">
    <visual><geometry><box size="0.4 0.3 0.1"/></geometry><material name="blue"><color rgba="0 0 1 1"/></material></visual>
    <collision><geometry><box size="0.4 0.3 0.1"/></geometry></collision>
    <inertial><mass value="5.0"/><inertia ixx="0.1" ixy="0" ixz="0" iyy="0.1" iyz="0" izz="0.1"/></inertial>
  </link>
  <link name="left_wheel">
    <visual><geometry><cylinder length="0.05" radius="0.1"/></geometry><material name="black"><color rgba="0 0 0 1"/></material></visual>
    <collision><geometry><cylinder length="0.05" radius="0.1"/></geometry></collision>
    <inertial><mass value="0.5"/><inertia ixx="0.01" ixy="0" ixz="0" iyy="0.01" iyz="0" izz="0.01"/></inertial>
  </link>
  <joint name="left_wheel_joint" type="continuous">
    <parent link="base_link"/><child link="left_wheel"/><origin xyz="0.1 0.175 0" rpy="1.5707 0 0"/><axis xyz="0 0 1"/>
  </joint>
  <link name="right_wheel">
    <visual><geometry><cylinder length="0.05" radius="0.1"/></geometry><material name="black"/></visual>
    <collision><geometry><cylinder length="0.05" radius="0.1"/></geometry></collision>
    <inertial><mass value="0.5"/><inertia ixx="0.01" ixy="0" ixz="0" iyy="0.01" iyz="0" izz="0.01"/></inertial>
  </link>
  <joint name="right_wheel_joint" type="continuous">
    <parent link="base_link"/><child link="right_wheel"/><origin xyz="0.1 -0.175 0" rpy="1.5707 0 0"/><axis xyz="0 0 1"/>
  </joint>
  <link name="caster_wheel">
    <visual><geometry><sphere radius="0.05"/></geometry></visual>
    <collision><geometry><sphere radius="0.05"/></geometry></collision>
  </link>
  <joint name="caster_joint" type="fixed">
    <parent link="base_link"/><child link="caster_wheel"/><origin xyz="-0.15 0 -0.05" rpy="0 0 0"/>
  </joint>
  <link name="lidar_link">
    <visual><geometry><cylinder length="0.05" radius="0.05"/></geometry><material name="red"><color rgba="1 0 0 1"/></material></visual>
  </link>
  <joint name="lidar_joint" type="fixed"><parent link="base_link"/><child link="lidar_link"/><origin xyz="0.15 0 0.075" rpy="0 0 0"/></joint>
  <gazebo>
    <plugin filename="gz-sim-diff-drive-system" name="gz::sim::systems::DiffDrive">
      <left_joint>left_wheel_joint</left_joint>
      <right_joint>right_wheel_joint</right_joint>
      <wheel_separation>0.35</wheel_separation>
      <wheel_radius>0.1</wheel_radius>
    </plugin>
  </gazebo>
</robot>
